<?xml version="1.0"?>
<robot xmlns:xacro="http://ros.org/wiki/xacro">

    <xacro:include filename="$(find ur_description)/urdf/robotiq_140/robotiq_140_gripper.transmission.xacro" />

    <xacro:macro name="robotiq_140_gripper" params="parent prefix">

        <joint name="${prefix}gripper_base_joint" type="fixed">
            <parent link="${prefix}${parent}"/>
            <child link="${prefix}gripper_base_link"/>
            <origin rpy="0.0 0.0 0.0" xyz="0.0 0.0 0.0"/>
        </joint>

        <link name="${prefix}gripper_base_link">
            <visual>
                <geometry>
                    <mesh filename="package://ur_description/meshes/robotiq_140/visual/robotiq_140_base_link.dae"/>
                </geometry>
            </visual>
            <inertial>
                <mass value="0.636951" />
                <origin xyz="0.0 0.0 0.0" />
                <inertia ixx = "0.000380" ixy = "0.000000" ixz = "0.000000"
                         iyx = "0.000000" iyy = "0.001110" iyz = "0.000000"
                         izx = "0.000000" izy = "0.000000" izz = "0.001171" />
            </inertial>
        </link>

        <joint name="${prefix}gripper_joint" type="revolute">
            <parent link="${prefix}gripper_base_link"/>
            <child link="${prefix}gripper_left_knuckle_link"/>
            <axis xyz="0 0 1"/>
            <origin rpy="${pi} 0.0 0.0" xyz="0.05490452 0.03060114 0.0"/>
            <limit lower="-0.402" upper="0.402" velocity="2.0" effort="1000"/>
        </joint>

        <joint name="${prefix}gripper_right_knuckle_joint" type="continuous">
            <parent link="${prefix}gripper_base_link"/>
            <child link="${prefix}gripper_right_knuckle_link"/>
            <axis xyz="0 0 1"/>
            <origin rpy="0.0 0.0 0.0" xyz="0.05490452 -0.03060114 0.0"/>
            <limit lower="-3.14" upper="3.14" velocity="100.0" effort="1000"/>
            <mimic joint="${prefix}gripper_joint"/>
        </joint>

        <link name="${prefix}gripper_left_knuckle_link">
            <visual>
                <geometry>
                    <mesh filename="package://ur_description/meshes/robotiq_140/visual/robotiq_140_knuckle_link.dae"/>
                </geometry>
            </visual>
            <inertial>
                <mass value="0.018491" />
                <origin xyz="0.0 0.0 0.0" />
                <inertia ixx = "0.000009" ixy = "-0.000001" ixz = "0.000000"
                         iyx = "-0.000001" iyy = "0.000001" iyz = "0.000000"
                         izx = "0.000000" izy = "0.000000" izz = "0.000010" />
            </inertial>
        </link>

        <link name="${prefix}gripper_right_knuckle_link">
            <visual>
                <geometry>
                    <mesh filename="package://ur_description/meshes/robotiq_140/visual/robotiq_140_knuckle_link.dae"/>
                </geometry>
            </visual>
            <inertial>
                <mass value="0.018491" />
                <origin xyz="0.0 0.0 0.0" />
                <inertia ixx = "0.000009" ixy = "-0.000001" ixz = "0.000000"
                         iyx = "-0.000001" iyy = "0.000001" iyz = "0.000000"
                         izx = "0.000000" izy = "0.000000" izz = "0.000010" />
            </inertial>
        </link>

        <joint name="${prefix}gripper_left_finger_joint" type="fixed">
            <parent link="${prefix}gripper_left_knuckle_link"/>
            <child link="${prefix}gripper_left_finger_link"/>
            <origin xyz="0.00795779 -0.03073656 0.0" rpy="0 0 0" />
        </joint>

        <joint name="${prefix}gripper_right_finger_joint" type="fixed">
            <parent link="${prefix}gripper_right_knuckle_link"/>
            <child link="${prefix}gripper_right_finger_link"/>
            <origin xyz="0.00795779 -0.03073656 0.0" rpy="0 0 0" />
        </joint>

        <link name="${prefix}gripper_left_finger_link">
            <visual>
                <geometry>
                    <mesh filename="package://ur_description/meshes/robotiq_140/visual/robotiq_140_finger_link.dae"/>
                </geometry>
            </visual>
            <inertial>
                <mass value="0.027309" />
                <origin xyz="0.0 0.0 0.0" />
                <inertia ixx = "0.000003" ixy = "-0.000002" ixz = "0.000000"
                         iyx = "-0.000002" iyy = "0.000021" iyz = "0.000000"
                         izx = "0.000000" izy = "0.000000" izz = "0.000020" />
            </inertial>
        </link>

        <link name="${prefix}gripper_right_finger_link">
            <visual>
                <geometry>
                    <mesh filename="package://ur_description/meshes/robotiq_140/visual/robotiq_140_finger_link.dae"/>
                </geometry>
            </visual>
            <inertial>
                <mass value="0.027309" />
                <origin xyz="0.0 0.0 0.0" />
                <inertia ixx = "0.000003" ixy = "-0.000002" ixz = "0.000000"
                         iyx = "-0.000002" iyy = "0.000021" iyz = "0.000000"
                         izx = "0.000000" izy = "0.000000" izz = "0.000020" />
            </inertial>
        </link>

        <joint name="${prefix}gripper_left_inner_knuckle_joint" type="continuous">
            <parent link="${prefix}gripper_base_link"/>
            <child link="${prefix}gripper_left_inner_knuckle_link"/>
            <axis xyz="0 0 1"/>
            <origin xyz="0.06142 0.0127 0" rpy="${pi} 0.0 0.0" />
            <limit lower="-3.14" upper="3.14" velocity="100.0" effort="0.1"/>
            <mimic joint="${prefix}gripper_joint" offset="0"/>
        </joint>

        <joint name="${prefix}gripper_right_inner_knuckle_joint" type="continuous">
            <parent link="${prefix}gripper_base_link"/>
            <child link="${prefix}gripper_right_inner_knuckle_link"/>
            <axis xyz="0 0 1"/>
            <origin xyz="0.06142 -0.0127 0" rpy="0 0 0"/>
            <limit lower="-3.14" upper="3.14" velocity="100.0" effort="0.1"/>
            <mimic joint="${prefix}gripper_joint" offset="0"/>
        </joint>

        <link name="${prefix}gripper_left_inner_knuckle_link">
            <visual>
                <geometry>
                    <mesh filename="package://ur_description/meshes/robotiq_140/visual/robotiq_140_inner_knuckle_link.dae"/>
                </geometry>
            </visual>
            <inertial>
                <mass value="0.029951" />
                <origin xyz="0.0 0.0 0.0" />
                <inertia ixx = "0.000039" ixy = "0.000000" ixz = "0.000000"
                         iyx = "0.000000" iyy = "0.000005" iyz = "0.000000"
                         izx = "0.000000" izy = "0.000000" izz = "0.000035" />
            </inertial>
        </link>
        <link name="${prefix}gripper_right_inner_knuckle_link">
            <visual>
                <geometry>
                    <mesh filename="package://ur_description/meshes/robotiq_140/visual/robotiq_140_inner_knuckle_link.dae"/>
                </geometry>
            </visual>
            <inertial>
                <mass value="0.029951" />
                <origin xyz="0.0 0.0 0.0" />
                <inertia ixx = "0.000039" ixy = "0.000000" ixz = "0.000000"
                         iyx = "0.000000" iyy = "0.000005" iyz = "0.000000"
                         izx = "0.000000" izy = "0.000000" izz = "0.000035" />
            </inertial>
        </link>

        <joint name="${prefix}gripper_left_finger_tip_joint" type="continuous">
            <parent link="${prefix}gripper_left_inner_knuckle_link"/>
            <child link="${prefix}gripper_left_finger_tip_link"/>
            <axis xyz="0 0 1"/>
            <origin xyz="0.09441861 -0.03294127 0.0" rpy="0.0 0.0 0.0"/>
            <limit lower="-3.14" upper="3.14" velocity="100.0" effort="0.1"/>
            <mimic joint="${prefix}gripper_joint" multiplier="-1"/>
        </joint>

        <joint name="${prefix}gripper_right_finger_tip_joint" type="continuous">
            <parent link="${prefix}gripper_right_inner_knuckle_link"/>
            <child link="${prefix}gripper_right_finger_tip_link"/>
            <axis xyz="0 0 1"/>
            <origin rpy="0.0 0.0 0.0" xyz="0.09441861 -0.03294127  0.0"/>
            <limit lower="-3.14" upper="3.14" velocity="100.0" effort="0.1"/>
            <mimic joint="${prefix}gripper_joint" multiplier="-1"/>
        </joint>


        <link name="${prefix}gripper_left_finger_tip_link">
            <visual>
                <geometry>
                    <mesh filename="package://ur_description/meshes/robotiq_140/visual/robotiq_140_finger_tip_link.dae"/>
                </geometry>
            </visual>
            <inertial>
                <mass value="0.019555" />
                <origin xyz="0.0 0.0 0.0" />
                <inertia ixx = "0.000002" ixy = "0.000000" ixz = "0.000000"
                         iyx = "0.000000" iyy = "0.000005" iyz = "0.000000"
                         izx = "0.000000" izy = "0.000000" izz = "0.000006" />
            </inertial>
                <xacro:if value="${gripper_collision_model == 'grasp'}">
                    <collision>
                        <origin xyz="0.025 0.005 0" rpy="0 0 0"/>
                        <geometry>
                            <box size="0.04 0.005 0.02" />
                        </geometry>
                    </collision>
                </xacro:if>
        </link>

        <link name="${prefix}gripper_right_finger_tip_link">
            <visual>
                <geometry>
                    <mesh filename="package://ur_description/meshes/robotiq_140/visual/robotiq_140_finger_tip_link.dae"/>
                </geometry>
            </visual>
            <inertial>
                <mass value="0.019555" />
                <origin xyz="0.0 0.0 0.0" />
                <inertia ixx = "0.000002" ixy = "0.000000" ixz = "0.000000"
                         iyx = "0.000000" iyy = "0.000005" iyz = "0.000000"
                         izx = "0.000000" izy = "0.000000" izz = "0.000006" />
            </inertial>
            <xacro:if value="${gripper_collision_model == 'grasp'}">
								<collision>
								    <origin xyz="0.025 0.005 0" rpy="0 0 0"/>
				            <geometry>
				               <box size="0.04 0.005 0.02" />
				            </geometry>
				        </collision>
						</xacro:if>
        </link>
	
	<!-- zero gravity to "fix" exploding gripper issue-->
	<gazebo reference="gripper_right_finger_tip_link">
	  <turnGravityOff>true</turnGravityOff>
	</gazebo>

	<gazebo reference="gripper_left_finger_tip_link">
	  <turnGravityOff>true</turnGravityOff>
	</gazebo>

	<gazebo reference="gripper_right_finger_link">
	  <turnGravityOff>true</turnGravityOff>
	</gazebo>

	<gazebo reference="gripper_left_finger_link">
	  <turnGravityOff>true</turnGravityOff>
	</gazebo>

	<gazebo reference="gripper_right_inner_knuckle_link">
	  <turnGravityOff>true</turnGravityOff>
	</gazebo>

	<gazebo reference="gripper_left_inner_knuckle_link">
	  <turnGravityOff>true</turnGravityOff>
	</gazebo>

        <gazebo>
        <!-- loading plugin: mimic joints works in gazebo now -->
          <plugin filename="libroboticsgroup_gazebo_mimic_joint_plugin.so" name="${prefix}mimic_robotiq_140_1">
            <robotNamespace>/ur10</robotNamespace>
            <joint>${prefix}gripper_joint</joint>
            <mimicJoint>${prefix}gripper_right_knuckle_joint</mimicJoint>
            <!--multiplier>1.0</multiplier>
            <offset>0.0</offset-->
          </plugin>

          <plugin filename="libroboticsgroup_gazebo_mimic_joint_plugin.so" name="${prefix}mimic_robotiq_140_2">
            <robotNamespace>/ur10</robotNamespace>
            <joint>${prefix}gripper_joint</joint>
            <mimicJoint>${prefix}gripper_left_inner_knuckle_joint</mimicJoint>
            <!--multiplier>1.0</multiplier>
            <offset>0.0</offset-->
          </plugin>

          <plugin filename="libroboticsgroup_gazebo_mimic_joint_plugin.so" name="${prefix}mimic_robotiq_140_3">
            <robotNamespace>/ur10</robotNamespace>
            <joint>${prefix}gripper_joint</joint>
            <mimicJoint>${prefix}gripper_right_inner_knuckle_joint</mimicJoint>
            <!--multiplier>1.0</multiplier>
            <offset>0.0</offset-->
          </plugin>

          <plugin filename="libroboticsgroup_gazebo_mimic_joint_plugin.so" name="${prefix}mimic_robotiq_140_4">
            <robotNamespace>/ur10</robotNamespace>
            <joint>${prefix}gripper_joint</joint>
            <mimicJoint>${prefix}gripper_left_finger_tip_joint</mimicJoint>
            <multiplier>-1.0</multiplier>
            <offset>0.0</offset>
          </plugin>

          <plugin filename="libroboticsgroup_gazebo_mimic_joint_plugin.so" name="${prefix}mimic_robotiq_140_5">
            <robotNamespace>/ur10</robotNamespace>
            <joint>${prefix}gripper_joint</joint>
            <mimicJoint>${prefix}gripper_right_finger_tip_joint</mimicJoint>
            <multiplier>-1.0</multiplier>
            <offset>0.0</offset>
          </plugin>
        </gazebo>

        <xacro:robotiq_140_gripper_transmission prefix="${prefix}" />

    </xacro:macro>
</robot>
