<?xml version="1.0" encoding="utf-8"?>
<!-- This URDF was automatically created by SolidWorks to URDF Exporter! Originally created by Stephen Brawner (brawner@gmail.com) 
     Commit Version: 1.6.0-4-g7f85cfe  Build Version: 1.6.7995.38578
     For more information, please see http://wiki.ros.org/sw_urdf_exporter -->
<robot
  name="fanuc">
  
  <link 
    name="world"/>
    
  <joint 
    name="base_joint" 
    type="fixed">
    <origin
      xyz="0 0 0"
      rpy="0 0 0" />
    <parent
      link="world" />
    <child
      link="base_link" />
  </joint>
  
  <link
    name="base_link">
    <inertial>
      <origin
        xyz="0 0 0"
        rpy="0 0 0" />
      <mass
        value="40" />
      <inertia
        ixx="19.25"
        ixy="0.22631"
        ixz="-3.4354"
        iyy="20.198"
        iyz="2.4676"
        izz="2.6464" />
    </inertial>
    <visual>
      <origin
        xyz="0 0 0"
        rpy="0 0 0" />
      <geometry>
        <mesh
          filename="package://fanuc/meshes/base_link.STL" />
      </geometry>
      <material
        name="">
        <color
          rgba="0.79608 0.82353 0.93725 1" />
      </material>
    </visual>
    <collision>
      <origin
        xyz="0 0 0"
        rpy="0 0 0" />
      <geometry>
        <mesh
          filename="package://fanuc/meshes/base_link.STL" />
      </geometry>
    </collision>
  </link>
  <link
    name="Link_1">
    <inertial>
      <origin
        xyz="0 0 0"
        rpy="0 0 0" />
      <mass
        value="40" />
      <inertia
        ixx="19.25"
        ixy="0.22631"
        ixz="-3.4354"
        iyy="20.198"
        iyz="2.4676"
        izz="2.6464" />
    </inertial>
    <visual>
      <origin
        xyz="0 0 0"
        rpy="0 0 0" />
      <geometry>
        <mesh
          filename="package://fanuc/meshes/Link_1.STL" />
      </geometry>
      <material
        name="">
        <color
          rgba="0.79608 0.82353 0.93725 1" />
      </material>
    </visual>
    <collision>
      <origin
        xyz="0 0 0"
        rpy="0 0 0" />
      <geometry>
        <mesh
          filename="package://fanuc/meshes/Link_1.STL" />
      </geometry>
    </collision>
  </link>
  <joint
    name="Joint_1"
    type="revolute">
    <origin
      xyz="0 -0.1277 0"
      rpy="1.5708 0 0" />
    <parent
      link="base_link" />
    <child
      link="Link_1" />
    <axis
      xyz="0 0 -1" />
    <limit
      lower="0"
      upper="6.632251"
      effort="0"
      velocity="2.094395" />
  </joint>
  <link
    name="Link_2">
    <inertial>
      <origin
        xyz="0 0 0"
        rpy="0 0 0" />
      <mass
        value="40" />
      <inertia
        ixx="19.25"
        ixy="0.22631"
        ixz="-3.4354"
        iyy="20.198"
        iyz="2.4676"
        izz="2.6464" />
    </inertial>
    <visual>
      <origin
        xyz="0 0 0"
        rpy="0 0 0" />
      <geometry>
        <mesh
          filename="package://fanuc/meshes/Link_2.STL" />
      </geometry>
      <material
        name="">
        <color
          rgba="1 1 1 1" />
      </material>
    </visual>
    <collision>
      <origin
        xyz="0 0 0"
        rpy="0 0 0" />
      <geometry>
        <mesh
          filename="package://fanuc/meshes/Link_2.STL" />
      </geometry>
    </collision>
  </link>
  <joint
    name="Joint_2"
    type="revolute">
    <origin
      xyz="0 0 0.1173"
      rpy="0 0 0" />
    <parent
      link="Link_1" />
    <child
      link="Link_2" />
    <axis
      xyz="0 -1 0" />
    <limit
      lower="0"
      upper="6.283185"
      effort="0"
      velocity="2.094395" />
  </joint>
  <link
    name="Link_3">
    <inertial>
      <origin
        xyz="0 0 0"
        rpy="0 0 0" />
      <mass
        value="40" />
      <inertia
        ixx="19.2503226285715"
        ixy="0.22631401696623"
        ixz="-3.43542873586211"
        iyy="20.1981005703131"
        iyz="2.46761396132132"
        izz="2.64638249491934" />
    </inertial>
    <visual>
      <origin
        xyz="0 0 0"
        rpy="0 0 0" />
      <geometry>
        <mesh
          filename="package://fanuc/meshes/Link_3.STL" />
      </geometry>
      <material
        name="">
        <color
          rgba="0.796078431372549 0.823529411764706 0.937254901960784 1" />
      </material>
    </visual>
    <collision>
      <origin
        xyz="0 0 0"
        rpy="0 0 0" />
      <geometry>
        <mesh
          filename="package://fanuc/meshes/Link_3.STL" />
      </geometry>
    </collision>
  </link>
  <joint
    name="Joint_3"
    type="revolute">
    <origin
      xyz="0 0 0.71"
      rpy="0 0 0" />
    <parent
      link="Link_2" />
    <child
      link="Link_3" />
    <axis
      xyz="0 -1 0" />
    <limit
      lower="0"
      upper="9.948377"
      effort="0"
      velocity="3.141593" />
  </joint>
  <link
    name="Link_4">
    <inertial>
      <origin
        xyz="0 0 0"
        rpy="0 0 0" />
      <mass
        value="40" />
      <inertia
        ixx="19.2503226285715"
        ixy="0.22631401696623"
        ixz="-3.43542873586211"
        iyy="20.1981005703131"
        iyz="2.46761396132132"
        izz="2.64638249491934" />
    </inertial>
    <visual>
      <origin
        xyz="0 0 0"
        rpy="0 0 0" />
      <geometry>
        <mesh
          filename="package://fanuc/meshes/Link_4.STL" />
      </geometry>
      <material
        name="">
        <color
          rgba="0.796078431372549 0.823529411764706 0.937254901960784 1" />
      </material>
    </visual>
    <collision>
      <origin
        xyz="0 0 0"
        rpy="0 0 0" />
      <geometry>
        <mesh
          filename="package://fanuc/meshes/Link_4.STL" />
      </geometry>
    </collision>
  </link>
  <joint
    name="Joint_4"
    type="revolute">
    <origin
      xyz="0.54 0 0"
      rpy="0 0 0" />
    <parent
      link="Link_3" />
    <child
      link="Link_4" />
    <axis
      xyz="-1 0 0" />
    <limit
      lower="0"
      upper="6.6323"
      effort="0"
      velocity="3.1416" />
  </joint>
  <link
    name="Link_5">
    <inertial>
      <origin
        xyz="0 0 0"
        rpy="0 0 0" />
      <mass
        value="40" />
      <inertia
        ixx="19.2503226285715"
        ixy="0.22631401696623"
        ixz="-3.43542873586211"
        iyy="20.1981005703131"
        iyz="2.46761396132132"
        izz="2.64638249491934" />
    </inertial>
    <visual>
      <origin
        xyz="0 0 0"
        rpy="0 0 0" />
      <geometry>
        <mesh
          filename="package://fanuc/meshes/Link_5.STL" />
      </geometry>
      <material
        name="">
        <color
          rgba="0.796078431372549 0.823529411764706 0.937254901960784 1" />
      </material>
    </visual>
    <collision>
      <origin
        xyz="0 0 0"
        rpy="0 0 0" />
      <geometry>
        <mesh
          filename="package://fanuc/meshes/Link_5.STL" />
      </geometry>
    </collision>
  </link>
  <joint
    name="Joint_5"
    type="revolute">
    <origin
      xyz="0 -0.15 0"
      rpy="0 0 0" />
    <parent
      link="Link_4" />
    <child
      link="Link_5" />
    <axis
      xyz="0 -1 0" />
    <limit
      lower="0"
      upper="6.2832"
      effort="0"
      velocity="3.1416" />
  </joint>
  <link
    name="Link_6">
    <inertial>
      <origin
        xyz="0 0 0"
        rpy="0 0 0" />
      <mass
        value="40" />
      <inertia
        ixx="19.2503226285715"
        ixy="0.22631401696623"
        ixz="-3.43542873586211"
        iyy="20.1981005703131"
        iyz="2.46761396132132"
        izz="2.64638249491934" />
    </inertial>
    <visual>
      <origin
        xyz="0 0 0"
        rpy="0 0 0" />
      <geometry>
        <mesh
          filename="package://fanuc/meshes/Link_6.STL" />
      </geometry>
      <material
        name="">
        <color
          rgba="0.792156862745098 0.819607843137255 0.933333333333333 1" />
      </material>
    </visual>
    <collision>
      <origin
        xyz="0 0 0"
        rpy="0 0 0" />
      <geometry>
        <mesh
          filename="package://fanuc/meshes/Link_6.STL" />
      </geometry>
    </collision>
  </link>
  <joint
    name="Joint_6"
    type="revolute">
    <origin
      xyz="0.16 0 0"
      rpy="0 0 0" />
    <parent
      link="Link_5" />
    <child
      link="Link_6" />
    <axis
      xyz="0 0 0" />
    <limit
      lower="0"
      upper="7.854"
      effort="0"
      velocity="3.1416" />
  </joint>
  
  <transmission 
    name="Link_1_Trans">
    <type>
      transmission_interface/SimpleTransmission
    </type>
    <joint 
    	name="Joint_1">
      <hardwareInterface>
        hardware_interface/PositionJointInterface
      </hardwareInterface>
    </joint>
    <actuator
      name="Joint_1_Motor">
      <hardwareInterface>
        hardware_interface/PositionJointInterface
      </hardwareInterface>
      <mechanicalReduction>1</mechanicalReduction>
    </actuator>
  </transmission>
  
  <transmission 
    name="Link_2_Trans">
    <type>
      transmission_interface/SimpleTransmission
    </type>
    <joint 
    	name="Joint_2">
      <hardwareInterface>
        hardware_interface/PositionJointInterface
      </hardwareInterface>
    </joint>
    <actuator
      name="Joint_2_Motor">
      <hardwareInterface>
        hardware_interface/PositionJointInterface
      </hardwareInterface>
      <mechanicalReduction>1</mechanicalReduction>
    </actuator>
  </transmission>
  
  <transmission 
    name="Link_3_Trans">
    <type>
      transmission_interface/SimpleTransmission
    </type>
    <joint 
    	name="Joint_3">
      <hardwareInterface>
        hardware_interface/PositionJointInterface
      </hardwareInterface>
    </joint>
    <actuator
      name="Joint_3_Motor">
      <hardwareInterface>
        hardware_interface/PositionJointInterface
      </hardwareInterface>
      <mechanicalReduction>1</mechanicalReduction>
    </actuator>
  </transmission>
  
  <transmission 
    name="Link_4_Trans">
    <type>
      transmission_interface/SimpleTransmission
    </type>
    <joint 
    	name="Joint_4">
      <hardwareInterface>
        hardware_interface/PositionJointInterface
      </hardwareInterface>
    </joint>
    <actuator
      name="Joint_4_Motor">
      <hardwareInterface>
        hardware_interface/PositionJointInterface
      </hardwareInterface>
      <mechanicalReduction>1</mechanicalReduction>
    </actuator>
  </transmission>
  
  <transmission 
    name="Link_5_Trans">
    <type>
      transmission_interface/SimpleTransmission
    </type>
    <joint 
    	name="Joint_5">
      <hardwareInterface>
        hardware_interface/PositionJointInterface
      </hardwareInterface>
    </joint>
    <actuator
      name="Joint_5_Motor">
      <hardwareInterface>
        hardware_interface/PositionJointInterface
      </hardwareInterface>
      <mechanicalReduction>1</mechanicalReduction>
    </actuator>
  </transmission>
  
  <transmission 
    name="Link_6_Trans">
    <type>
      transmission_interface/SimpleTransmission
    </type>
    <joint 
    	name="Joint_6">
      <hardwareInterface>
        hardware_interface/PositionJointInterface
      </hardwareInterface>
    </joint>
    <actuator
      name="Joint_6_Motor">
      <hardwareInterface>
        hardware_interface/PositionJointInterface
      </hardwareInterface>
      <mechanicalReduction>1</mechanicalReduction>
    </actuator>
  </transmission>

  <gazebo>
    <plugin
      name="control"
      filename="libgazebo_ros_control.so">
      <robotNamespace>/</robotNamespace>
    </plugin>
  </gazebo>
  
  <gazebo
    reference="Link_1">
    <selfCollide>true</selfCollide>
  </gazebo>
  
  <gazebo
    reference="Link_2">
    <selfCollide>true</selfCollide>
  </gazebo>
  
  <gazebo
    reference="Link_3">
    <selfCollide>true</selfCollide>
  </gazebo>
  
  <gazebo
    reference="Link_4">
    <selfCollide>true</selfCollide>
  </gazebo>
  
  <gazebo
    reference="Link_5">
    <selfCollide>true</selfCollide>
  </gazebo>
  
  <gazebo
    reference="Link_6">
    <selfCollide>true</selfCollide>
  </gazebo>
  
</robot>
