<?xml version="1.0" encoding="utf-8"?>
<!-- This URDF was automatically created by SolidWorks to URDF Exporter! Originally created by Stephen Brawner (brawner@gmail.com) 
     Commit Version: 1.6.0-4-g7f85cfe  Build Version: 1.6.7995.38578
     For more information, please see http://wiki.ros.org/sw_urdf_exporter -->
<robot
  name="fanuc">
  
  <link 
    name="world"/>
    
  <joint 
    name="base_joint" 
    type="fixed">
    <origin
      xyz="0 0 0.0"
      rpy="-1.57 0 0" />
    <parent
      link="world" />
    <child
      link="base_link" />
  </joint>
  
  <link
    name="base_link">
    <inertial>
      <origin xyz="-0.00329048 -0.02033528 0.00093672"/>
      <mass value="9.92000000"/>
      <inertia ixx="0.02528990" ixy="-0.00030938" ixz="-0.00000638" iyy="0.04289183" iyz="0.00000276" izz="0.02888818"/>
    </inertial>

    <visual>
      <origin
        xyz="0 0 0"
        rpy="0 0 0" />
      <geometry>
        <mesh
          filename="package://fanuc/meshes/base_link.STL" />
      </geometry>
      <material
        name="">
        <color
          rgba="0.79608 0.82353 0.93725 1" />
      </material>
    </visual>
    <collision>
      <origin
        xyz="0 0 0"
        rpy="0 0 0" />
      <geometry>
        <mesh
          filename="package://fanuc/meshes/base_link.STL" />
      </geometry>
    </collision>
  </link>
  
  <link
    name="Link_1">
    <inertial>
      <origin xyz="-0.00506694 0.00467160 0.11028854"/>
      <mass value="3.84000000"/>
      <inertia ixx="0.02569997" ixy="-0.00000034" ixz="-0.00000014" iyy="0.02211221" iyz="0.00168942" izz="0.01667992"/>
    </inertial>


    <visual>
      <origin
        xyz="0 0 0"
        rpy="0 0 0" />
      <geometry>
        <mesh
          filename="package://fanuc/meshes/Link_1.STL" />
      </geometry>
      <material
        name="">
        <color
          rgba="0.79608 0.82353 0.93725 1" />
      </material>
    </visual>
    <collision>
      <origin
        xyz="0 0 0"
        rpy="0 0 0" />
      <geometry>
        <mesh
          filename="package://fanuc/meshes/Link_1.STL" />
      </geometry>
    </collision>
  </link>
  
  <joint
    name="Joint_1"
    type="revolute">
    <origin
      xyz="0 -0.1277 0"
      rpy="1.5708 0 0" />
    <parent
      link="base_link" />
    <child
      link="Link_1" />
    <axis
      xyz="0 0 -1" />
    <limit
      lower="-3.31613"
      upper="3.31613"
      effort="50"
      velocity="2.094395" />
  </joint>
  
  <link
    name="Link_2">
    <inertial>
      <origin xyz="0.00051231 -0.24024661 0.38801491"/>
      <mass value="11.52000000"/>
      <inertia ixx="0.67622107" ixy="0.00000567" ixz="0.00002455" iyy="0.66076284" iyz="-0.02211019" izz="0.05165074"/>
    </inertial>

    <visual>
      <origin
        xyz="0 0 0"
        rpy="0 0 0" />
      <geometry>
        <mesh
          filename="package://fanuc/meshes/Link_2.STL" />
      </geometry>
      <material
        name="">
        <color
          rgba="1 1 1 1" />
      </material>
    </visual>
    <collision>
      <origin
        xyz="0 0 0"
        rpy="0 0 0" />
      <geometry>
        <mesh
          filename="package://fanuc/meshes/Link_2.STL" />
      </geometry>
    </collision>
  </link>
  
  <joint
    name="Joint_2"
    type="revolute">
    <origin
      xyz="0 0 0.1173"
      rpy="0 0 0" />
    <parent
      link="Link_1" />
    <child
      link="Link_2" />
    <axis
      xyz="0 -1 0" />
    <limit
      lower="-3.14159"
      upper="3.14159"
      effort="45"
      velocity="2.094395" />
  </joint>
  
  <link
    name="Link_3">
    <inertial>
      <origin xyz="0.01750312 0.02330679 -0.00063791"/>
      <mass value="2.88000000"/>
      <inertia ixx="0.00684691" ixy="-0.00047246" ixz="0.00000038" iyy="0.01280498" iyz="0.00000009" izz="0.01307738"/>
    </inertial>

    <visual>
      <origin
        xyz="0 0 0"
        rpy="0 0 0" />
      <geometry>
        <mesh
          filename="package://fanuc/meshes/Link_3.STL" />
      </geometry>
      <material
        name="">
        <color
          rgba="0.796078431372549 0.823529411764706 0.937254901960784 1" />
      </material>
    </visual>
    <collision>
      <origin
        xyz="0 0 0"
        rpy="0 0 0" />
      <geometry>
        <mesh
          filename="package://fanuc/meshes/Link_3.STL" />
      </geometry>
    </collision>
  </link>
  
  <joint
    name="Joint_3"
    type="revolute">
    <origin
      xyz="0 0 0.71"
      rpy="0 0 0" />
    <parent
      link="Link_2" />
    <child
      link="Link_3" />
    <axis
      xyz="0 -1 0" />
    <limit
      lower="-4.97419"
      upper="4.97419"
      effort="40"
      velocity="3.141593" />
  </joint>
  
  <link
    name="Link_4">
    <inertial>
      <origin xyz="-0.02240763 0.00549191 -0.00001857"/>
      <mass value="8.64000000"/>
      <inertia ixx="0.01445615" ixy="0.00238610" ixz="0.00000151" iyy="0.13431462" iyz="0.00000302" izz="0.13541640"/>
    </inertial>

    <visual>
      <origin
        xyz="0 0 0"
        rpy="0 0 0" />
      <geometry>
        <mesh
          filename="package://fanuc/meshes/Link_4.STL" />
      </geometry>
      <material
        name="">
        <color
          rgba="0.796078431372549 0.823529411764706 0.937254901960784 1" />
      </material>
    </visual>
    <collision>
      <origin
        xyz="0 0 0"
        rpy="0 0 0" />
      <geometry>
        <mesh
          filename="package://fanuc/meshes/Link_4.STL" />
      </geometry>
    </collision>
  </link>
  
  <joint
    name="Joint_4"
    type="revolute">
    <origin
      xyz="0.54 0 0"
      rpy="0 0 0" />
    <parent
      link="Link_3" />
    <child
      link="Link_4" />
    <axis
      xyz="-1 0 0" />
    <limit
      lower="-3.31615"
      upper="3.31615"
      effort="34.8"
      velocity="3.1416" />
  </joint>
  
  <link
    name="Link_5">
    <inertial>
      <origin xyz="0.00048703 0.00243462 -0.00008948"/>
      <mass value="1.60000000"/>
      <inertia ixx="0.00311136" ixy="0.00029011" ixz="-0.00000001" iyy="0.00354547" iyz="-0.00000000" izz="0.00441730"/>
    </inertial>

    <visual>
      <origin
        xyz="0 0 0"
        rpy="0 0 0" />
      <geometry>
        <mesh
          filename="package://fanuc/meshes/Link_5.STL" />
      </geometry>
      <material
        name="">
        <color
          rgba="0.796078431372549 0.823529411764706 0.937254901960784 1" />
      </material>
    </visual>
    <collision>
      <origin
        xyz="0 0 0"
        rpy="0 0 0" />
      <geometry>
        <mesh
          filename="package://fanuc/meshes/Link_5.STL" />
      </geometry>
    </collision>
  </link>
  
  <joint
    name="Joint_5"
    type="revolute">
    <origin
      xyz="0 -0.15 0"
      rpy="0 0 0" />
    <parent
      link="Link_4" />
    <child
      link="Link_5" />
    <axis
      xyz="0 -1 0" />
    <limit
      lower="-3.14159"
      upper="3.14159"
      effort="26"
      velocity="3.1416" />
  </joint>
  
  <link
    name="Link_6">
    <inertial>
      <origin xyz="-0.01318563 0.00056378 -0.00024276"/>
      <mass value="1.60000000"/>
      <inertia ixx="0.00177658" ixy="0.00000062" ixz="-0.00000001" iyy="0.00120978" iyz="0.00000003" izz="0.00141833"/>
    </inertial>

    <visual>
      <origin
        xyz="0 0 0"
        rpy="0 0 0" />
      <geometry>
        <mesh
          filename="package://fanuc/meshes/Link_6.STL" />
      </geometry>
      <material
        name="">
        <color
          rgba="0.792156862745098 0.819607843137255 0.933333333333333 1" />
      </material>
    </visual>
    <collision>
      <origin
        xyz="0 0 0"
        rpy="0 0 0" />
      <geometry>
        <mesh
          filename="package://fanuc/meshes/Link_6.STL" />
      </geometry>
    </collision>
  </link>
  
  <joint
    name="Joint_6"
    type="revolute">
    <origin
      xyz="0.16 0 0"
      rpy="0 0 0" />
    <parent
      link="Link_5" />
    <child
      link="Link_6" />
    <axis
      xyz="1 0 0" />
    <limit
      lower="-3.927"
      upper="3.927"
      effort="11"
      velocity="3.1416" />
  </joint>
  
  <transmission 
    name="Link_1_Trans">
    <type>
      transmission_interface/SimpleTransmission
    </type>
    <joint 
    	name="Joint_1">
      <hardwareInterface>
        hardware_interface/PositionJointInterface
      </hardwareInterface>
    </joint>
    <actuator
      name="Joint_1_Motor">
      <hardwareInterface>
        hardware_interface/PositionJointInterface
      </hardwareInterface>
      <mechanicalReduction>1</mechanicalReduction>
    </actuator>
  </transmission>
  
  <transmission 
    name="Link_2_Trans">
    <type>
      transmission_interface/SimpleTransmission
    </type>
    <joint 
    	name="Joint_2">
      <hardwareInterface>
        hardware_interface/PositionJointInterface
      </hardwareInterface>
    </joint>
    <actuator
      name="Joint_2_Motor">
      <hardwareInterface>
        hardware_interface/PositionJointInterface
      </hardwareInterface>
      <mechanicalReduction>1</mechanicalReduction>
    </actuator>
  </transmission>
  
  <transmission 
    name="Link_3_Trans">
    <type>
      transmission_interface/SimpleTransmission
    </type>
    <joint 
    	name="Joint_3">
      <hardwareInterface>
        hardware_interface/PositionJointInterface
      </hardwareInterface>
    </joint>
    <actuator
      name="Joint_3_Motor">
      <hardwareInterface>
        hardware_interface/PositionJointInterface
      </hardwareInterface>
      <mechanicalReduction>1</mechanicalReduction>
    </actuator>
  </transmission>
  
  <transmission 
    name="Link_4_Trans">
    <type>
      transmission_interface/SimpleTransmission
    </type>
    <joint 
    	name="Joint_4">
      <hardwareInterface>
        hardware_interface/PositionJointInterface
      </hardwareInterface>
    </joint>
    <actuator
      name="Joint_4_Motor">
      <hardwareInterface>
        hardware_interface/PositionJointInterface
      </hardwareInterface>
      <mechanicalReduction>1</mechanicalReduction>
    </actuator>
  </transmission>
  
  <transmission 
    name="Link_5_Trans">
    <type>
      transmission_interface/SimpleTransmission
    </type>
    <joint 
    	name="Joint_5">
      <hardwareInterface>
        hardware_interface/PositionJointInterface
      </hardwareInterface>
    </joint>
    <actuator
      name="Joint_5_Motor">
      <hardwareInterface>
        hardware_interface/PositionJointInterface
      </hardwareInterface>
      <mechanicalReduction>1</mechanicalReduction>
    </actuator>
  </transmission>
  
  <transmission 
    name="Link_6_Trans">
    <type>
      transmission_interface/SimpleTransmission
    </type>
    <joint 
    	name="Joint_6">
      <hardwareInterface>
        hardware_interface/PositionJointInterface
      </hardwareInterface>
    </joint>
    <actuator
      name="Joint_6_Motor">
      <hardwareInterface>
        hardware_interface/PositionJointInterface
      </hardwareInterface>
      <mechanicalReduction>1</mechanicalReduction>
    </actuator>
  </transmission>

  <gazebo>
    <plugin
      name="control"
      filename="libgazebo_ros_control.so">
      <robotNamespace>/</robotNamespace>
    </plugin>
  </gazebo>
  
  <gazebo
    reference="Link_1">
    <selfCollide>true</selfCollide>
  </gazebo>
  
  <gazebo
    reference="Link_2">
    <selfCollide>true</selfCollide>
  </gazebo>
  
  <gazebo
    reference="Link_3">
    <selfCollide>true</selfCollide>
  </gazebo>
  
  <gazebo
    reference="Link_4">
    <selfCollide>true</selfCollide>
  </gazebo>
  
  <gazebo
    reference="Link_5">
    <selfCollide>true</selfCollide>
  </gazebo>
  
  <gazebo
    reference="Link_6">
    <selfCollide>true</selfCollide>
  </gazebo>
  
</robot>
