<robot name="ur10" xmlns:xacro="http://ros.org/wiki/xacro">
    <!-- measured from model -->
    <link name="base_link">
      <visual>
        <geometry>
          <mesh filename="package://ur_description/meshes/ur10/visual/base.dae"/>
        </geometry>
      </visual>
      <inertial>
        <mass value="4.0"/>
        <origin rpy="0 0 0" xyz="0.0 0.0 0.0"/>
        <inertia ixx="0.0061063308908" ixy="0.0" ixz="0.0" iyy="0.0061063308908" iyz="0.0" izz="0.01125"/>
      </inertial>
    </link>
    <joint name="shoulder_pan_joint" type="revolute">
      <parent link="base_link"/>
      <child link="shoulder_link"/>
      <origin rpy="0.0 0.0 0.0" xyz="0.0 0.0 0.1273"/>
      <axis xyz="0 0 1"/>
      <limit effort="330.0" lower="-3.14" upper="3.14" velocity="2.16"/>
      <dynamics damping="0.0" friction="0.0"/>
    </joint>
    <link name="shoulder_link">
      <visual>
        <geometry>
          <mesh filename="package://ur_description/meshes/ur10/visual/shoulder.dae"/>
        </geometry>
      </visual>
      <collision>
        <origin rpy="0 0 0" xyz="0 0 0.0"/>
        <geometry>
          <sphere radius="0.11"/>
        </geometry>
      </collision>
      <inertial>
        <mass value="7.778"/>
        <origin rpy="0 0 0" xyz="0.0 0.0 0.0"/>
        <inertia ixx="0.0314743125769" ixy="0.0" ixz="0.0" iyy="0.0314743125769" iyz="0.0" izz="0.021875625"/>
      </inertial>
    </link>
    <joint name="shoulder_lift_joint" type="revolute">
      <parent link="shoulder_link"/>
      <child link="upper_arm_link"/>
      <origin rpy="0.0 1.57 0.0" xyz="0.0 0.220941 0.0"/>
      <axis xyz="0 1 0"/>
      <limit effort="330.0" lower="-3.14" upper="3.14" velocity="2.16"/>
      <dynamics damping="0.0" friction="0.0"/>
    </joint>
    <link name="upper_arm_link">
      <visual>
        <geometry>
          <mesh filename="package://ur_description/meshes/ur10/visual/upperarm.dae"/>
        </geometry>
      </visual>
      <collision>
        <origin rpy="0 0 0" xyz="0 -0.05 0.3"/>
        <geometry>
          <cylinder length="0.6" radius="0.11"/>
        </geometry>
      </collision>
      <collision>
        <origin rpy="0 0 0" xyz="0 -0.05 0"/>
        <geometry>
          <sphere radius="0.11"/>
        </geometry>
      </collision>
      <collision>
        <origin rpy="0 0 0" xyz="0 -0.05 0.6"/>
        <geometry>
          <sphere radius="0.11"/>
        </geometry>
      </collision>
      <inertial>
        <mass value="12.93"/>
        <origin rpy="0 0 0" xyz="0.0 0.0 0.306"/>
        <inertia ixx="0.421753803798" ixy="0.0" ixz="0.0" iyy="0.421753803798" iyz="0.0" izz="0.036365625"/>
      </inertial>
    </link>
    <joint name="elbow_joint" type="revolute">
      <parent link="upper_arm_link"/>
      <child link="forearm_link"/>
      <origin rpy="0.0 0.0 0.0" xyz="0.0 -0.1719 0.612"/>
      <axis xyz="0 1 0"/>
      <limit effort="150.0" lower="-3.14" upper="3.14" velocity="3.15"/>
      <dynamics damping="0.0" friction="0.0"/>
    </joint>
    <link name="forearm_link">
      <visual>
        <geometry>
          <mesh filename="package://ur_description/meshes/ur10/visual/forearm.dae"/>
        </geometry>
      </visual>
      <collision>
        <origin rpy="0 0 0" xyz="0 0 0.28"/>
        <geometry>
          <cylinder length="0.56" radius="0.08"/>
        </geometry>
      </collision>
      <collision>
        <origin rpy="0 0 0" xyz="0 0 0.56"/>
        <geometry>
          <sphere radius="0.08"/>
        </geometry>
      </collision>
      <collision>
        <origin rpy="0 0 0" xyz="0 0 0"/>
        <geometry>
          <sphere radius="0.08"/>
        </geometry>
      </collision>
      <inertial>
        <mass value="3.87"/>
        <origin rpy="0 0 0" xyz="0.0 0.0 0.28615"/>
        <inertia ixx="0.111069694097" ixy="0.0" ixz="0.0" iyy="0.111069694097" iyz="0.0" izz="0.010884375"/>
      </inertial>
    </link>
    <joint name="wrist_1_joint" type="revolute">
      <parent link="forearm_link"/>
      <child link="wrist_1_link"/>
      <origin rpy="0.0 1.57 0.0" xyz="0.0 0.0 0.5723"/>
      <axis xyz="0 1 0"/>
      <limit effort="54.0" lower="-3.14" upper="3.14" velocity="3.2"/>
      <dynamics damping="0.0" friction="0.0"/>
    </joint>
    <link name="wrist_1_link">
      <visual>
        <geometry>
          <mesh filename="package://ur_description/meshes/ur10/visual/wrist1.dae"/>
        </geometry>
      </visual>
      <collision>
        <origin rpy="0 0 0" xyz="0 0.1149 0"/>
        <geometry>
          <sphere radius="0.08"/>
        </geometry>
      </collision>
      <inertial>
        <mass value="1.96"/>
        <origin rpy="0 0 0" xyz="0.0 0.0 0.0"/>
        <inertia ixx="0.0051082479567" ixy="0.0" ixz="0.0" iyy="0.0051082479567" iyz="0.0" izz="0.0055125"/>
      </inertial>
    </link>
    <joint name="wrist_2_joint" type="revolute">
      <parent link="wrist_1_link"/>
      <child link="wrist_2_link"/>
      <origin rpy="0.0 0.0 0.0" xyz="0.0 0.1149 0.0"/>
      <axis xyz="0 0 1"/>
      <limit effort="54.0" lower="-3.14" upper="3.14" velocity="3.2"/>
      <dynamics damping="0.0" friction="0.0"/>
    </joint>
    <link name="wrist_2_link">
      <visual>
        <geometry>
          <mesh filename="package://ur_description/meshes/ur10/visual/wrist2.dae"/>
        </geometry>
      </visual>
      <collision>
        <origin rpy="0 0 0" xyz="0 0 0.1157"/>
        <geometry>
          <sphere radius="0.08"/>
        </geometry>
      </collision>
      <inertial>
        <mass value="1.96"/>
        <origin rpy="0 0 0" xyz="0.0 0.0 0.0"/>
        <inertia ixx="0.0051082479567" ixy="0.0" ixz="0.0" iyy="0.0051082479567" iyz="0.0" izz="0.0055125"/>
      </inertial>
    </link>
    <joint name="wrist_3_joint" type="revolute">
      <parent link="wrist_2_link"/>
      <child link="wrist_3_link"/>
      <origin rpy="0.0 0.0 0.0" xyz="0.0 0.0 0.1157"/>
      <axis xyz="0 1 0"/>
      <limit effort="54.0" lower="-3.14" upper="3.14" velocity="3.2"/>
      <dynamics damping="0.0" friction="0.0"/>
    </joint>
    <link name="wrist_3_link">
      <visual>
        <geometry>
          <mesh filename="package://ur_description/meshes/ur10/visual/wrist3.dae"/>
        </geometry>
      </visual>
      <collision>
        <origin rpy="0 0 0" xyz="0 0.2622 0"/>
        <geometry>
          <sphere radius="0.1"/>
        </geometry>
      </collision>
      <inertial>
        <mass value="0.202"/>
        <origin rpy="0 0 0" xyz="0.0 0.0 0.0"/>
        <inertia ixx="0.000526462289415" ixy="0.0" ixz="0.0" iyy="0.000526462289415" iyz="0.0" izz="0.000568125"/>
      </inertial>
    </link>
    <joint name="ee_fixed_joint" type="fixed">
      <parent link="wrist_3_link"/>
      <child link="ee_link"/>
      <origin rpy="0.0 0.0 1.57" xyz="0.0 0.0922 0.0"/>
    </joint>
    <link name="ee_link"/>
    <transmission name="shoulder_pan_trans">
      <type>transmission_interface/SimpleTransmission</type>
      <joint name="shoulder_pan_joint">
        <hardwareInterface>hardware_interface/VelocityJointInterface</hardwareInterface>
      </joint>
      <actuator name="shoulder_pan_motor">
        <mechanicalReduction>1</mechanicalReduction>
        <hardwareInterface>hardware_interface/VelocityJointInterface</hardwareInterface>
      </actuator>
    </transmission>
    <transmission name="shoulder_lift_trans">
      <type>transmission_interface/SimpleTransmission</type>
      <joint name="shoulder_lift_joint">
        <hardwareInterface>hardware_interface/VelocityJointInterface</hardwareInterface>
      </joint>
      <actuator name="shoulder_lift_motor">
        <mechanicalReduction>1</mechanicalReduction>
        <hardwareInterface>hardware_interface/VelocityJointInterface</hardwareInterface>
      </actuator>
    </transmission>
    <transmission name="elbow_trans">
      <type>transmission_interface/SimpleTransmission</type>
      <joint name="elbow_joint">
        <hardwareInterface>hardware_interface/VelocityJointInterface</hardwareInterface>
      </joint>
      <actuator name="elbow_motor">
        <mechanicalReduction>1</mechanicalReduction>
        <hardwareInterface>hardware_interface/VelocityJointInterface</hardwareInterface>
      </actuator>
    </transmission>
    <transmission name="wrist_1_trans">
      <type>transmission_interface/SimpleTransmission</type>
      <joint name="wrist_1_joint">
        <hardwareInterface>hardware_interface/VelocityJointInterface</hardwareInterface>
      </joint>
      <actuator name="wrist_1_motor">
        <mechanicalReduction>1</mechanicalReduction>
        <hardwareInterface>hardware_interface/VelocityJointInterface</hardwareInterface>
      </actuator>
    </transmission>
    <transmission name="wrist_2_trans">
      <type>transmission_interface/SimpleTransmission</type>
      <joint name="wrist_2_joint">
        <hardwareInterface>hardware_interface/VelocityJointInterface</hardwareInterface>
      </joint>
      <actuator name="wrist_2_motor">
        <mechanicalReduction>1</mechanicalReduction>
        <hardwareInterface>hardware_interface/VelocityJointInterface</hardwareInterface>
      </actuator>
    </transmission>
    <transmission name="wrist_3_trans">
      <type>transmission_interface/SimpleTransmission</type>
      <joint name="wrist_3_joint">
        <hardwareInterface>hardware_interface/VelocityJointInterface</hardwareInterface>
      </joint>
      <actuator name="wrist_3_motor">
        <mechanicalReduction>1</mechanicalReduction>
        <hardwareInterface>hardware_interface/VelocityJointInterface</hardwareInterface>
      </actuator>
    </transmission>
    <joint name="robotiq_140_base_joint" type="fixed">
      <parent link="ee_link"/>
      <child link="robotiq_140_base_link"/>
      <origin rpy="0.0 0.0 0.0" xyz="0.03 0.0 0.0"/>
      <!-- 3cm for force-torque sensor. TODO: replace by real model -->
    </joint>
    <link name="robotiq_140_base_link">
      <visual>
        <geometry>
          <mesh filename="package://ur_description/meshes/robotiq_140/visual/robotiq_140_base_link.dae"/>
        </geometry>
      </visual>
      <inertial>
        <mass value="0.636951"/>
        <origin xyz="0.0 0.0 0.0"/>
        <inertia ixx="0.000380" ixy="0.000000" ixz="0.000000" iyx="0.000000" iyy="0.001110" iyz="0.000000" izx="0.000000" izy="0.000000" izz="0.001171"/>
      </inertial>
    </link>
    <joint name="robotiq_140_left_knuckle_joint" type="revolute">
      <parent link="robotiq_140_base_link"/>
      <child link="robotiq_140_left_knuckle_link"/>
      <axis xyz="0 0 1"/>
      <origin rpy="3.14 0.0 0.0" xyz="0.05490452 0.03060114 0.0"/>
      <limit effort="1000" lower="-0.402" upper="0.402" velocity="2.0"/>
    </joint>
    <joint name="robotiq_140_right_knuckle_joint" type="continuous">
      <parent link="robotiq_140_base_link"/>
      <child link="robotiq_140_right_knuckle_link"/>
      <axis xyz="0 0 1"/>
      <origin rpy="0.0 0.0 0.0" xyz="0.05490452 -0.03060114 0.0"/>
      <limit effort="1000" lower="-3.14" upper="3.14" velocity="100.0"/>
      <mimic joint="robotiq_140_left_knuckle_joint"/>
    </joint>
    <link name="robotiq_140_left_knuckle_link">
      <visual>
        <geometry>
          <mesh filename="package://ur_description/meshes/robotiq_140/visual/robotiq_140_knuckle_link.dae"/>
        </geometry>
      </visual>
      <inertial>
        <mass value="0.018491"/>
        <origin xyz="0.0 0.0 0.0"/>
        <inertia ixx="0.000009" ixy="-0.000001" ixz="0.000000" iyx="-0.000001" iyy="0.000001" iyz="0.000000" izx="0.000000" izy="0.000000" izz="0.000010"/>
      </inertial>
    </link>
    <link name="robotiq_140_right_knuckle_link">
      <visual>
        <geometry>
          <mesh filename="package://ur_description/meshes/robotiq_140/visual/robotiq_140_knuckle_link.dae"/>
        </geometry>
      </visual>
      <inertial>
        <mass value="0.018491"/>
        <origin xyz="0.0 0.0 0.0"/>
        <inertia ixx="0.000009" ixy="-0.000001" ixz="0.000000" iyx="-0.000001" iyy="0.000001" iyz="0.000000" izx="0.000000" izy="0.000000" izz="0.000010"/>
      </inertial>
    </link>
    <joint name="robotiq_140_left_finger_joint" type="fixed">
      <parent link="robotiq_140_left_knuckle_link"/>
      <child link="robotiq_140_left_finger_link"/>
      <origin rpy="0 0 0" xyz="0.00795779 -0.03073656 0.0"/>
    </joint>
    <joint name="robotiq_140_right_finger_joint" type="fixed">
      <parent link="robotiq_140_right_knuckle_link"/>
      <child link="robotiq_140_right_finger_link"/>
      <origin rpy="0 0 0" xyz="0.00795779 -0.03073656 0.0"/>
    </joint>
    <link name="robotiq_140_left_finger_link">
      <visual>
        <geometry>
          <mesh filename="package://ur_description/meshes/robotiq_140/visual/robotiq_140_finger_link.dae"/>
        </geometry>
      </visual>
      <inertial>
        <mass value="0.027309"/>
        <origin xyz="0.0 0.0 0.0"/>
        <inertia ixx="0.000003" ixy="-0.000002" ixz="0.000000" iyx="-0.000002" iyy="0.000021" iyz="0.000000" izx="0.000000" izy="0.000000" izz="0.000020"/>
      </inertial>
    </link>
    <link name="robotiq_140_right_finger_link">
      <visual>
        <geometry>
          <mesh filename="package://ur_description/meshes/robotiq_140/visual/robotiq_140_finger_link.dae"/>
        </geometry>
      </visual>
      <inertial>
        <mass value="0.027309"/>
        <origin xyz="0.0 0.0 0.0"/>
        <inertia ixx="0.000003" ixy="-0.000002" ixz="0.000000" iyx="-0.000002" iyy="0.000021" iyz="0.000000" izx="0.000000" izy="0.000000" izz="0.000020"/>
      </inertial>
    </link>
    <joint name="robotiq_140_left_inner_knuckle_joint" type="continuous">
      <parent link="robotiq_140_base_link"/>
      <child link="robotiq_140_left_inner_knuckle_link"/>
      <axis xyz="0 0 1"/>
      <origin rpy="3.14 0.0 0.0" xyz="0.06142 0.0127 0"/>
      <limit effort="0.1" lower="-3.14" upper="3.14" velocity="100.0"/>
      <mimic joint="robotiq_140_left_knuckle_joint" offset="0"/>
    </joint>
    <joint name="robotiq_140_right_inner_knuckle_joint" type="continuous">
      <parent link="robotiq_140_base_link"/>
      <child link="robotiq_140_right_inner_knuckle_link"/>
      <axis xyz="0 0 1"/>
      <origin rpy="0 0 0" xyz="0.06142 -0.0127 0"/>
      <limit effort="0.1" lower="-3.14" upper="3.14" velocity="100.0"/>
      <mimic joint="robotiq_140_left_knuckle_joint" offset="0"/>
    </joint>
    <link name="robotiq_140_left_inner_knuckle_link">
      <visual>
        <geometry>
          <mesh filename="package://ur_description/meshes/robotiq_140/visual/robotiq_140_inner_knuckle_link.dae"/>
        </geometry>
      </visual>
      <inertial>
        <mass value="0.029951"/>
        <origin xyz="0.0 0.0 0.0"/>
        <inertia ixx="0.000039" ixy="0.000000" ixz="0.000000" iyx="0.000000" iyy="0.000005" iyz="0.000000" izx="0.000000" izy="0.000000" izz="0.000035"/>
      </inertial>
    </link>
    <link name="robotiq_140_right_inner_knuckle_link">
      <visual>
        <geometry>
          <mesh filename="package://ur_description/meshes/robotiq_140/visual/robotiq_140_inner_knuckle_link.dae"/>
        </geometry>
      </visual>
      <inertial>
        <mass value="0.029951"/>
        <origin xyz="0.0 0.0 0.0"/>
        <inertia ixx="0.000039" ixy="0.000000" ixz="0.000000" iyx="0.000000" iyy="0.000005" iyz="0.000000" izx="0.000000" izy="0.000000" izz="0.000035"/>
      </inertial>
    </link>
    <joint name="robotiq_140_left_finger_tip_joint" type="continuous">
      <parent link="robotiq_140_left_inner_knuckle_link"/>
      <child link="robotiq_140_left_finger_tip_link"/>
      <axis xyz="0 0 1"/>
      <origin rpy="0.0 0.0 0.0" xyz="0.09441861 -0.03294127 0.0"/>
      <limit effort="0.1" lower="-3.14" upper="3.14" velocity="100.0"/>
      <mimic joint="robotiq_140_left_knuckle_joint" multiplier="-1"/>
    </joint>
    <joint name="robotiq_140_right_finger_tip_joint" type="continuous">
      <parent link="robotiq_140_right_inner_knuckle_link"/>
      <child link="robotiq_140_right_finger_tip_link"/>
      <axis xyz="0 0 1"/>
      <origin rpy="0.0 0.0 0.0" xyz="0.09441861 -0.03294127  0.0"/>
      <limit effort="0.1" lower="-3.14" upper="3.14" velocity="100.0"/>
      <mimic joint="robotiq_140_left_knuckle_joint" multiplier="-1"/>
    </joint>
    <link name="robotiq_140_left_finger_tip_link">
      <visual>
        <geometry>
          <mesh filename="package://ur_description/meshes/robotiq_140/visual/robotiq_140_finger_tip_link.dae"/>
        </geometry>
      </visual>
      <inertial>
        <mass value="0.019555"/>
        <origin xyz="0.0 0.0 0.0"/>
        <inertia ixx="0.000002" ixy="0.000000" ixz="0.000000" iyx="0.000000" iyy="0.000005" iyz="0.000000" izx="0.000000" izy="0.000000" izz="0.000006"/>
      </inertial>
    </link>
    <link name="robotiq_140_right_finger_tip_link">
      <visual>
        <geometry>
          <mesh filename="package://ur_description/meshes/robotiq_140/visual/robotiq_140_finger_tip_link.dae"/>
        </geometry>
      </visual>
      <inertial>
        <mass value="0.019555"/>
        <origin xyz="0.0 0.0 0.0"/>
        <inertia ixx="0.000002" ixy="0.000000" ixz="0.000000" iyx="0.000000" iyy="0.000005" iyz="0.000000" izx="0.000000" izy="0.000000" izz="0.000006"/>
      </inertial>
    </link>
    <gazebo>
      <!-- loading plugin: mimic joints works in gazebo now -->
      <plugin filename="libroboticsgroup_gazebo_mimic_joint_plugin.so" name="mimic_robotiq_140_1">
        <robotNamespace>/ur10</robotNamespace>
        <joint>robotiq_140_left_knuckle_joint</joint>
        <mimicJoint>robotiq_140_right_knuckle_joint</mimicJoint>
        <!--multiplier>1.0</multiplier>
              <offset>0.0</offset-->
      </plugin>
      <plugin filename="libroboticsgroup_gazebo_mimic_joint_plugin.so" name="mimic_robotiq_140_2">
        <robotNamespace>/ur10</robotNamespace>
        <joint>robotiq_140_left_knuckle_joint</joint>
        <mimicJoint>robotiq_140_left_inner_knuckle_joint</mimicJoint>
        <!--multiplier>1.0</multiplier>
              <offset>0.0</offset-->
      </plugin>
      <plugin filename="libroboticsgroup_gazebo_mimic_joint_plugin.so" name="mimic_robotiq_140_3">
        <robotNamespace>/ur10</robotNamespace>
        <joint>robotiq_140_left_knuckle_joint</joint>
        <mimicJoint>robotiq_140_right_inner_knuckle_joint</mimicJoint>
        <!--multiplier>1.0</multiplier>
              <offset>0.0</offset-->
      </plugin>
      <plugin filename="libroboticsgroup_gazebo_mimic_joint_plugin.so" name="mimic_robotiq_140_4">
        <robotNamespace>/ur10</robotNamespace>
        <joint>robotiq_140_left_knuckle_joint</joint>
        <mimicJoint>robotiq_140_left_finger_tip_joint</mimicJoint>
        <multiplier>-1.0</multiplier>
        <offset>0.0</offset>
      </plugin>
      <plugin filename="libroboticsgroup_gazebo_mimic_joint_plugin.so" name="mimic_robotiq_140_5">
        <robotNamespace>/ur10</robotNamespace>
        <joint>robotiq_140_left_knuckle_joint</joint>
        <mimicJoint>robotiq_140_right_finger_tip_joint</mimicJoint>
        <multiplier>-1.0</multiplier>
        <offset>0.0</offset>
      </plugin>
    </gazebo>
    <transmission name="robotiq_140_left_knuckle_trans">
      <type>transmission_interface/SimpleTransmission</type>
      <joint name="robotiq_140_left_knuckle_joint">
        <hardwareInterface>hardware_interface/PositionJointInterface</hardwareInterface>
      </joint>
      <actuator name="robotiq_140_left_knuckle_motor">
        <mechanicalReduction>1</mechanicalReduction>
        <hardwareInterface>hardware_interface/PositionJointInterface</hardwareInterface>
      </actuator>
    </transmission>
    <link name="pedestal_link">
      <visual>
        <origin rpy="0.0 0.0 0.0" xyz="-0.23 -0.33 -0.013"/>
        <geometry>
          <mesh filename="package://ur_description/meshes/rst_ft/rst_base.stl" scale="0.0255 0.0255 0.0253"/>
        </geometry>
        <material name="darkgray"/>
      </visual>
      <collision>
        <origin rpy="0 0 0" xyz="0 0 0.38"/>
        <geometry>
          <cylinder length="0.76" radius="0.1"/>
        </geometry>
      </collision>
      <collision>
        <origin rpy="0 0 0" xyz="0 0 0.76"/>
        <geometry>
          <sphere radius="0.1"/>
        </geometry>
      </collision>
    </link>
    <joint name="mount" type="fixed">
      <origin rpy="0 0 0" xyz="0.0 0.0 0.8"/>
      <parent link="pedestal_link"/>
      <child link="base_link"/>
    </joint>
    <link name="world"/>
    <joint name="world_joint" type="fixed">
      <parent link="world"/>
      <child link="pedestal_link"/>
      <origin rpy="0.0 0.0 0.0" xyz="0.0 0.0 0.0"/>
    </joint>
    <gazebo reference="pedestal_link">
      <turnGravityOff>1</turnGravityOff>
    </gazebo>
    <gazebo reference="base_link">
      <turnGravityOff>1</turnGravityOff>
    </gazebo>
    <gazebo reference="shoulder_link">
      <turnGravityOff>1</turnGravityOff>
    </gazebo>
    <gazebo reference="upper_arm_link">
      <turnGravityOff>1</turnGravityOff>
    </gazebo>
    <gazebo reference="forearm_link">
      <turnGravityOff>1</turnGravityOff>
    </gazebo>
    <gazebo reference="wrist_1_link">
      <turnGravityOff>1</turnGravityOff>
    </gazebo>
    <gazebo reference="wrist_2_link">
      <turnGravityOff>1</turnGravityOff>
    </gazebo>
    <gazebo reference="wrist_3_link">
      <turnGravityOff>1</turnGravityOff>
    </gazebo>
    <gazebo reference="ee_link">
      <turnGravityOff>1</turnGravityOff>
    </gazebo>
    <gazebo>
      <plugin filename="libgazebo_ros_control.so" name="gazebo_ros_control">
        <robotNamespace>/ur10</robotNamespace>
      </plugin>
    </gazebo>
  </robot>